<?xml version="1.0" ?>
<!-- =================================================================================== -->
<!-- |    This document was autogenerated by xacro from mors.xacro                     | -->
<!-- |    EDITING THIS FILE BY HAND IS NOT RECOMMENDED                                 | -->
<!-- =================================================================================== -->
<robot name="mors_sim">
  <material name="black">
    <color rgba="0.0 0.0 0.0 1.0"/>
  </material>
  <material name="blue">
    <color rgba="0.0 0.0 0.8 1.0"/>
  </material>
  <material name="green">
    <color rgba="0.0 0.8 0.0 1.0"/>
  </material>
  <material name="grey">
    <color rgba="0.2 0.2 0.2 1.0"/>
  </material>
  <material name="silver">
    <color rgba="0.9137254901960784 0.9137254901960784 0.8470588235294118 1.0"/>
  </material>
  <material name="orange">
    <color rgba="1.0 0.4235294117647059 0.0392156862745098 1.0"/>
  </material>
  <material name="brown">
    <color rgba="0.8705882352941177 0.8117647058823529 0.7647058823529411 1.0"/>
  </material>
  <material name="white_gray">
    <color rgba="0.8235294117647058 0.8235294117647058 0.8235294117647058 1.0"/>
  </material>
  <material name="gold">
    <color rgba="0.8117647058823529 0.6784313725490196 0.30196078431372547 1.0"/>
  </material>
  <material name="white_blue">
    <color rgba="0.4627450980392157 0.8 0.9921568627450981 1.0"/>
  </material>
  <material name="white_black">
    <color rgba="0.49411764705882355 0.49411764705882355 0.49411764705882355 1.0"/>
  </material>
  <material name="red">
    <color rgba="0.8 0.0 0.0 1.0"/>
  </material>
  <material name="white">
    <color rgba="1.0 1.0 1.0 1.0"/>
  </material>
  <!-- candidate -->
  <!-- body -->
  <link name="base_link">
    <visual>
      <geometry>
        <box size="0.212 0.204 0.088"/>
      </geometry>
      <origin rpy="0 0 0" xyz="0 0 0"/>
      <material name="silver"/>
    </visual>
    <collision>
      <origin rpy="0 0 0" xyz="0 0 0"/>
      <geometry>
        <box size="0.212 0.204 0.088"/>
      </geometry>
    </collision>
    <!-- <inertial>
        <origin rpy="0 0 0" xyz="-0.00272 0.000875 0.000178"/>
        <mass value="0.001"/>
        <inertia ixx="0.000001" ixy="0.000001" ixz="0.000001" iyy="0.000001" iyz="0.000001" izz="0.000001"/>
      </inertial> -->
    <inertial>
      <origin rpy="0 0 0" xyz="-0.00272 0.000875 0.000178"/>
      <mass value="3.748"/>
      <inertia ixx="0.012838176" ixy="-6.851e-06" ixz="0.000156493" iyy="0.056852389" iyz="-9.5392e-05" izz="0.064034355"/>
    </inertial>
  </link>
  <!-- <link name="base_inertia">
      <inertial>
        <origin rpy="0 0 0" xyz="${body_cog_x} ${body_cog_y} ${body_cog_z}"/>
        <mass value="${body_mass}"/>
        <inertia ixx="${body_ixx}" ixy="${body_ixy}" ixz="${body_ixz}"
          iyy="${body_iyy}" iyz="${body_iyz}"
          izz="${body_izz}" />
      </inertial>
    </link>
    <joint name="base_link_to_base_inertia" type="fixed">
        <parent link="base_link"/>
        <child link="base_inertia"/>
        <origin rpy="0 0 0" xyz="0 0 0"/>
    </joint> -->
  <!-- abad -->
  <joint name="abad_joint_R1" type="revolute">
    <parent link="base_link"/>
    <child link="abad_R1"/>
    <origin rpy="-1.5707963267948966 0.0 -1.5707963267948966" xyz="0.1065 -0.067 0.0"/>
    <axis xyz="0 0 1"/>
    <dynamics damping="0.4" friction="0.55"/>
    <limit effort="2000" lower="-2.6179938779914944" upper="2.6179938779914944" velocity="30.0"/>
  </joint>
  <link name="abad_R1">
    <visual>
      <origin rpy="0 0 0" xyz="0 0 0.0295"/>
      <geometry>
        <cylinder length="0.059" radius="0.01"/>
      </geometry>
      <material name="white_blue"/>
    </visual>
    <collision>
      <origin rpy="0 0 0" xyz="0 0 0.0295"/>
      <geometry>
        <cylinder length="0.059" radius="0.01"/>
      </geometry>
    </collision>
    <inertial>
      <origin rpy="0 0 1.5707963267948966" xyz="-0.00606 -1.8e-05 0.058144"/>
      <mass value="0.309"/>
      <inertia ixx="0.000178705" ixy="-1.02e-07" ixz="-3.483e-06" iyy="0.000161337" iyz="-5e-09" izz="0.0001003"/>
    </inertial>
  </link>
  <!-- Hip-->
  <joint name="hip_joint_R1" type="revolute">
    <parent link="abad_R1"/>
    <child link="hip_R1"/>
    <origin rpy="1.5707963267948966 0.0 1.5707963267948966" xyz="0.0215 0.0 0.059"/>
    <axis xyz="0 0 1"/>
    <dynamics damping="0.4" friction="0.55"/>
    <limit effort="2000" lower="-2.6179938779914944" upper="2.6179938779914944" velocity="30.0"/>
  </joint>
  <link name="hip_R1">
    <visual>
      <origin rpy="0 1.5707963267948966 0" xyz="0.065 0 0.03"/>
      <geometry>
        <cylinder length="0.13" radius="0.01"/>
      </geometry>
      <material name="silver"/>
    </visual>
    <collision>
      <origin rpy="0 1.5707963267948966 0" xyz="0.065 0 0.03"/>
      <geometry>
        <cylinder length="0.13" radius="0.01"/>
      </geometry>
    </collision>
    <inertial>
      <origin rpy="0 0 0" xyz="0.034385 -0.000226 0.04482"/>
      <mass value="0.532"/>
      <inertia ixx="0.000279734" ixy="2.8e-07" ixz="-0.00025377" iyy="0.001715204" iyz="-1.2e-06" izz="0.001731949"/>
    </inertial>
  </link>
  <!-- Knee -->
  <joint name="knee_joint_R1" type="revolute">
    <parent link="hip_R1"/>
    <child link="knee_R1"/>
    <origin rpy="3.141592653589793 3.141592653589793 3.141592653589793" xyz="0.13 0.0 0.0645"/>
    <axis xyz="0 0 1"/>
    <dynamics damping="0.4" friction="0.55"/>
    <limit effort="2000" lower="-2.6179938779914944" upper="2.6179938779914944" velocity="30.0"/>
  </joint>
  <link name="knee_R1">
    <visual>
      <origin rpy="0 1.5707963267948966 0" xyz="0.07425 0 0.012"/>
      <geometry>
        <cylinder length="0.1485" radius="0.005"/>
      </geometry>
      <material name="white_blue"/>
    </visual>
    <collision>
      <origin rpy="0 1.5707963267948966 0" xyz="0.07425 0 0.012"/>
      <geometry>
        <cylinder length="0.1485" radius="0.005"/>
      </geometry>
    </collision>
    <inertial>
      <origin rpy="0 0 0" xyz="0.058408 0.0 0.009288"/>
      <mass value="0.049"/>
      <inertia ixx="3.796e-06" ixy="0.0" ixz="-7.744e-06" iyy="0.000208824" iyz="0.0" izz="0.00020873"/>
    </inertial>
  </link>
  <link name="ef_R1">
    <visual>
      <origin rpy="0 0 0" xyz="0 0 0"/>
      <geometry>
        <sphere radius="0.015"/>
      </geometry>
      <material name="white_blue"/>
    </visual>
    <collision>
      <geometry>
        <sphere radius="0.015"/>
      </geometry>
    </collision>
    <inertial>
      <origin rpy="0 0 0" xyz="-0.00272 0.000875 0.000178"/>
      <mass value="0.018"/>
      <inertia ixx="0.0000014" ixy="0.0" ixz="0.0" iyy="0.0000014" iyz="0.0" izz="0.0000014"/>
    </inertial>
  </link>
  <!-- End Effector-->
  <joint name="ef_joint_R1" type="fixed">
    <parent link="knee_R1"/>
    <child link="ef_R1"/>
    <origin rpy="0 0 0" xyz="0.1485 0.0 0.012"/>
  </joint>
  <!-- abad -->
  <joint name="abad_joint_L1" type="revolute">
    <parent link="base_link"/>
    <child link="abad_L1"/>
    <origin rpy="1.5707963267948966 0.0 1.5707963267948966" xyz="0.1065 0.067 0.0"/>
    <axis xyz="0 0 1"/>
    <dynamics damping="0.4" friction="0.55"/>
    <limit effort="2000" lower="-2.6179938779914944" upper="2.6179938779914944" velocity="30.0"/>
  </joint>
  <link name="abad_L1">
    <visual>
      <origin rpy="0 0 0" xyz="0 0 0.0295"/>
      <geometry>
        <cylinder length="0.059" radius="0.01"/>
      </geometry>
      <material name="white_blue"/>
    </visual>
    <collision>
      <origin rpy="0 0 0" xyz="0 0 0.0295"/>
      <geometry>
        <cylinder length="0.059" radius="0.01"/>
      </geometry>
    </collision>
    <inertial>
      <origin rpy="0 0 1.5707963267948966" xyz="-0.00606 -1.8e-05 0.058144"/>
      <mass value="0.309"/>
      <inertia ixx="0.000178705" ixy="-1.02e-07" ixz="-3.483e-06" iyy="0.000161337" iyz="-5e-09" izz="0.0001003"/>
    </inertial>
  </link>
  <!-- Hip-->
  <joint name="hip_joint_L1" type="revolute">
    <parent link="abad_L1"/>
    <child link="hip_L1"/>
    <origin rpy="-1.5707963267948966 0.0 -1.5707963267948966" xyz="0.0215 0.0 0.059"/>
    <axis xyz="0 0 1"/>
    <dynamics damping="0.4" friction="0.55"/>
    <limit effort="2000" lower="-2.6179938779914944" upper="2.6179938779914944" velocity="30.0"/>
  </joint>
  <link name="hip_L1">
    <visual>
      <origin rpy="0 1.5707963267948966 0" xyz="0.065 0 0.03"/>
      <geometry>
        <cylinder length="0.13" radius="0.01"/>
      </geometry>
      <material name="silver"/>
    </visual>
    <collision>
      <origin rpy="0 1.5707963267948966 0" xyz="0.065 0 0.03"/>
      <geometry>
        <cylinder length="0.13" radius="0.01"/>
      </geometry>
    </collision>
    <inertial>
      <origin rpy="0 0 0" xyz="0.034385 -0.000226 0.04482"/>
      <mass value="0.532"/>
      <inertia ixx="0.000279734" ixy="2.8e-07" ixz="-0.00025377" iyy="0.001715204" iyz="-1.2e-06" izz="0.001731949"/>
    </inertial>
  </link>
  <!-- Knee -->
  <joint name="knee_joint_L1" type="revolute">
    <parent link="hip_L1"/>
    <child link="knee_L1"/>
    <origin rpy="3.141592653589793 3.141592653589793 3.141592653589793" xyz="0.13 0.0 0.0645"/>
    <axis xyz="0 0 1"/>
    <dynamics damping="0.4" friction="0.55"/>
    <limit effort="2000" lower="-2.6179938779914944" upper="2.6179938779914944" velocity="30.0"/>
  </joint>
  <link name="knee_L1">
    <visual>
      <origin rpy="0 1.5707963267948966 0" xyz="0.07425 0 0.012"/>
      <geometry>
        <cylinder length="0.1485" radius="0.005"/>
      </geometry>
      <material name="white_blue"/>
    </visual>
    <collision>
      <origin rpy="0 1.5707963267948966 0" xyz="0.07425 0 0.012"/>
      <geometry>
        <cylinder length="0.1485" radius="0.005"/>
      </geometry>
    </collision>
    <inertial>
      <origin rpy="0 0 0" xyz="0.058408 0.0 0.009288"/>
      <mass value="0.049"/>
      <inertia ixx="3.796e-06" ixy="0.0" ixz="-7.744e-06" iyy="0.000208824" iyz="0.0" izz="0.00020873"/>
    </inertial>
  </link>
  <link name="ef_L1">
    <visual>
      <origin rpy="0 0 0" xyz="0 0 0"/>
      <geometry>
        <sphere radius="0.015"/>
      </geometry>
      <material name="white_blue"/>
    </visual>
    <collision>
      <geometry>
        <sphere radius="0.015"/>
      </geometry>
    </collision>
    <inertial>
      <origin rpy="0 0 0" xyz="-0.00272 0.000875 0.000178"/>
      <mass value="0.018"/>
      <inertia ixx="0.0000014" ixy="0.0" ixz="0.0" iyy="0.0000014" iyz="0.0" izz="0.0000014"/>
    </inertial>
  </link>
  <!-- End Effector-->
  <joint name="ef_joint_L1" type="fixed">
    <parent link="knee_L1"/>
    <child link="ef_L1"/>
    <origin rpy="0 0 0" xyz="0.1485 0.0 0.012"/>
  </joint>
  <!-- abad -->
  <joint name="abad_joint_R2" type="revolute">
    <parent link="base_link"/>
    <child link="abad_R2"/>
    <origin rpy="1.5707963267948966 0.0 -1.5707963267948966" xyz="-0.1065 -0.067 0.0"/>
    <axis xyz="0 0 1"/>
    <dynamics damping="0.4" friction="0.55"/>
    <limit effort="2000" lower="-2.6179938779914944" upper="2.6179938779914944" velocity="30.0"/>
  </joint>
  <link name="abad_R2">
    <visual>
      <origin rpy="0 0 0" xyz="0 0 0.0295"/>
      <geometry>
        <cylinder length="0.059" radius="0.01"/>
      </geometry>
      <material name="white_blue"/>
    </visual>
    <collision>
      <origin rpy="0 0 0" xyz="0 0 0.0295"/>
      <geometry>
        <cylinder length="0.059" radius="0.01"/>
      </geometry>
    </collision>
    <inertial>
      <origin rpy="0 0 1.5707963267948966" xyz="-0.00606 -1.8e-05 0.058144"/>
      <mass value="0.309"/>
      <inertia ixx="0.000178705" ixy="-1.02e-07" ixz="-3.483e-06" iyy="0.000161337" iyz="-5e-09" izz="0.0001003"/>
    </inertial>
  </link>
  <!-- Hip-->
  <joint name="hip_joint_R2" type="revolute">
    <parent link="abad_R2"/>
    <child link="hip_R2"/>
    <origin rpy="-1.5707963267948966 0.0 -1.5707963267948966" xyz="0.0215 0.0 0.059"/>
    <axis xyz="0 0 1"/>
    <dynamics damping="0.4" friction="0.55"/>
    <limit effort="2000" lower="-2.6179938779914944" upper="2.6179938779914944" velocity="30.0"/>
  </joint>
  <link name="hip_R2">
    <visual>
      <origin rpy="0 1.5707963267948966 0" xyz="0.065 0 0.03"/>
      <geometry>
        <cylinder length="0.13" radius="0.01"/>
      </geometry>
      <material name="silver"/>
    </visual>
    <collision>
      <origin rpy="0 1.5707963267948966 0" xyz="0.065 0 0.03"/>
      <geometry>
        <cylinder length="0.13" radius="0.01"/>
      </geometry>
    </collision>
    <inertial>
      <origin rpy="0 0 0" xyz="0.034385 -0.000226 0.04482"/>
      <mass value="0.532"/>
      <inertia ixx="0.000279734" ixy="2.8e-07" ixz="-0.00025377" iyy="0.001715204" iyz="-1.2e-06" izz="0.001731949"/>
    </inertial>
  </link>
  <!-- Knee -->
  <joint name="knee_joint_R2" type="revolute">
    <parent link="hip_R2"/>
    <child link="knee_R2"/>
    <origin rpy="3.141592653589793 3.141592653589793 3.141592653589793" xyz="0.13 0.0 0.0645"/>
    <axis xyz="0 0 1"/>
    <dynamics damping="0.4" friction="0.55"/>
    <limit effort="2000" lower="-2.6179938779914944" upper="2.6179938779914944" velocity="30.0"/>
  </joint>
  <link name="knee_R2">
    <visual>
      <origin rpy="0 1.5707963267948966 0" xyz="0.07425 0 0.012"/>
      <geometry>
        <cylinder length="0.1485" radius="0.005"/>
      </geometry>
      <material name="white_blue"/>
    </visual>
    <collision>
      <origin rpy="0 1.5707963267948966 0" xyz="0.07425 0 0.012"/>
      <geometry>
        <cylinder length="0.1485" radius="0.005"/>
      </geometry>
    </collision>
    <inertial>
      <origin rpy="0 0 0" xyz="0.058408 0.0 0.009288"/>
      <mass value="0.049"/>
      <inertia ixx="3.796e-06" ixy="0.0" ixz="-7.744e-06" iyy="0.000208824" iyz="0.0" izz="0.00020873"/>
    </inertial>
  </link>
  <link name="ef_R2">
    <visual>
      <origin rpy="0 0 0" xyz="0 0 0"/>
      <geometry>
        <sphere radius="0.015"/>
      </geometry>
      <material name="white_blue"/>
    </visual>
    <collision>
      <geometry>
        <sphere radius="0.015"/>
      </geometry>
    </collision>
    <inertial>
      <origin rpy="0 0 0" xyz="-0.00272 0.000875 0.000178"/>
      <mass value="0.018"/>
      <inertia ixx="0.0000014" ixy="0.0" ixz="0.0" iyy="0.0000014" iyz="0.0" izz="0.0000014"/>
    </inertial>
  </link>
  <!-- End Effector-->
  <joint name="ef_joint_R2" type="fixed">
    <parent link="knee_R2"/>
    <child link="ef_R2"/>
    <origin rpy="0 0 0" xyz="0.1485 0.0 0.012"/>
  </joint>
  <!-- abad -->
  <joint name="abad_joint_L2" type="revolute">
    <parent link="base_link"/>
    <child link="abad_L2"/>
    <origin rpy="-1.5707963267948966 0.0 1.5707963267948966" xyz="-0.1065 0.067 0.0"/>
    <axis xyz="0 0 1"/>
    <dynamics damping="0.4" friction="0.55"/>
    <limit effort="2000" lower="-2.6179938779914944" upper="2.6179938779914944" velocity="30.0"/>
  </joint>
  <link name="abad_L2">
    <visual>
      <origin rpy="0 0 0" xyz="0 0 0.0295"/>
      <geometry>
        <cylinder length="0.059" radius="0.01"/>
      </geometry>
      <material name="white_blue"/>
    </visual>
    <collision>
      <origin rpy="0 0 0" xyz="0 0 0.0295"/>
      <geometry>
        <cylinder length="0.059" radius="0.01"/>
      </geometry>
    </collision>
    <inertial>
      <origin rpy="0 0 1.5707963267948966" xyz="-0.00606 -1.8e-05 0.058144"/>
      <mass value="0.309"/>
      <inertia ixx="0.000178705" ixy="-1.02e-07" ixz="-3.483e-06" iyy="0.000161337" iyz="-5e-09" izz="0.0001003"/>
    </inertial>
  </link>
  <!-- Hip-->
  <joint name="hip_joint_L2" type="revolute">
    <parent link="abad_L2"/>
    <child link="hip_L2"/>
    <origin rpy="1.5707963267948966 0.0 1.5707963267948966" xyz="0.0215 0.0 0.059"/>
    <axis xyz="0 0 1"/>
    <dynamics damping="0.4" friction="0.55"/>
    <limit effort="2000" lower="-2.6179938779914944" upper="2.6179938779914944" velocity="30.0"/>
  </joint>
  <link name="hip_L2">
    <visual>
      <origin rpy="0 1.5707963267948966 0" xyz="0.065 0 0.03"/>
      <geometry>
        <cylinder length="0.13" radius="0.01"/>
      </geometry>
      <material name="silver"/>
    </visual>
    <collision>
      <origin rpy="0 1.5707963267948966 0" xyz="0.065 0 0.03"/>
      <geometry>
        <cylinder length="0.13" radius="0.01"/>
      </geometry>
    </collision>
    <inertial>
      <origin rpy="0 0 0" xyz="0.034385 -0.000226 0.04482"/>
      <mass value="0.532"/>
      <inertia ixx="0.000279734" ixy="2.8e-07" ixz="-0.00025377" iyy="0.001715204" iyz="-1.2e-06" izz="0.001731949"/>
    </inertial>
  </link>
  <!-- Knee -->
  <joint name="knee_joint_L2" type="revolute">
    <parent link="hip_L2"/>
    <child link="knee_L2"/>
    <origin rpy="3.141592653589793 3.141592653589793 3.141592653589793" xyz="0.13 0.0 0.0645"/>
    <axis xyz="0 0 1"/>
    <dynamics damping="0.4" friction="0.55"/>
    <limit effort="2000" lower="-2.6179938779914944" upper="2.6179938779914944" velocity="30.0"/>
  </joint>
  <link name="knee_L2">
    <visual>
      <origin rpy="0 1.5707963267948966 0" xyz="0.07425 0 0.012"/>
      <geometry>
        <cylinder length="0.1485" radius="0.005"/>
      </geometry>
      <material name="white_blue"/>
    </visual>
    <collision>
      <origin rpy="0 1.5707963267948966 0" xyz="0.07425 0 0.012"/>
      <geometry>
        <cylinder length="0.1485" radius="0.005"/>
      </geometry>
    </collision>
    <inertial>
      <origin rpy="0 0 0" xyz="0.058408 0.0 0.009288"/>
      <mass value="0.049"/>
      <inertia ixx="3.796e-06" ixy="0.0" ixz="-7.744e-06" iyy="0.000208824" iyz="0.0" izz="0.00020873"/>
    </inertial>
  </link>
  <link name="ef_L2">
    <visual>
      <origin rpy="0 0 0" xyz="0 0 0"/>
      <geometry>
        <sphere radius="0.015"/>
      </geometry>
      <material name="white_blue"/>
    </visual>
    <collision>
      <geometry>
        <sphere radius="0.015"/>
      </geometry>
    </collision>
    <inertial>
      <origin rpy="0 0 0" xyz="-0.00272 0.000875 0.000178"/>
      <mass value="0.018"/>
      <inertia ixx="0.0000014" ixy="0.0" ixz="0.0" iyy="0.0000014" iyz="0.0" izz="0.0000014"/>
    </inertial>
  </link>
  <!-- End Effector-->
  <joint name="ef_joint_L2" type="fixed">
    <parent link="knee_L2"/>
    <child link="ef_L2"/>
    <origin rpy="0 0 0" xyz="0.1485 0.0 0.012"/>
  </joint>
</robot>
